<?xml version='1.0' encoding='UTF-8'?>
<!-- Universal Animal Template: unimal -->
<mujoco model="unimal">
  <compiler angle="degree"/>
  <size njmax="2000" nconmax="500"/>
  <option timestep=".005">
    <flag filterparent="disable"/>
  </option>
  <!-- Common defaults to make search space tractable -->
  <default>
    <!-- Define motor defaults -->
    <motor ctrlrange="-1 1" ctrllimited="true"/>
    <!-- Define joint defaults -->
    <default class="normal_joint">
      <joint type="hinge" damping="1" stiffness="1" armature="1" limited="true" range="-120 120" solimplimit="0 0.99 0.01"/>
    </default>
    <default class="walker_joint">
      <joint type="hinge" damping="0.2" stiffness="1" armature=".01" limited="true" range="-120 120" solimplimit="0 0.99 0.01"/>
    </default>
    <default class="stiff_joint">
      <joint type="hinge" damping="5" stiffness="10" armature=".01" limited="true" solimplimit="0 0.99 0.01"/>
    </default>
    <default class="free">
      <joint limited="false" damping="0" armature="0" stiffness="0"/>
    </default>
    <default class="growth_site">
      <site size="1e-6 1e-6 1e-6"/>
    </default>
    <default class="torso_growth_site">
      <site size="1e-6 1e-6 1e-6"/>
    </default>
    <default class="mirror_growth_site">
      <site size="1e-6 1e-6 1e-6"/>
    </default>
    <default class="btm_pos_site">
      <site size="1e-6 1e-6 1e-6"/>
    </default>
    <default class="box_face_site">
      <site size="1e-6 1e-6 1e-6"/>
    </default>
    <default class="imu_vel">
      <site type="box" size="0.05" rgba="1 0 0 0"/>
    </default>
    <default class="touch_site">
      <site group="3" rgba="0 0 1 .3"/>
    </default>
    <default class="food_site">
      <site material="food" size="0.15"/>
    </default>
    <!-- Define geom defaults -->
    <geom type="capsule" condim="3" friction="0.7 0.1 0.1" material="self"/>
  </default>
  <worldbody>
    <light diffuse="1 1 1" directional="true" exponent="1" pos="0 0 8" specular="0.1 0.1 0.1" dir="0 0 -1"/>
    <!-- <geom name="floor" type="plane" pos="0 0 0" size="50 50 1" material="grid"/> -->
    <!-- Programatically generated xml goes here -->
    <body name="torso/0" pos="0 0 0.5">
      <joint name="root" type="free" class="free"/>
      <site name="root" class="imu_vel"/>
      <geom name="torso/0" type="sphere" size="0.1" condim="3" density="600"/>
      <camera name="side" pos="0 -7 2" xyaxes="1 0 0 0 1 2" mode="trackcom"/>
      <site name="torso/0" class="growth_site" pos="0 0 0"/>
      <site name="torso/btm_pos/0" class="btm_pos_site" pos="0 0 -0.1"/>
      <site name="torso/touch/0" class="touch_site" size="0.11"/>
      <site name="torso/horizontal_y/0" class="torso_growth_site" pos="-0.1 0 0"/>
      <body name="limb/0" pos="0.07 0.07 0.0">
        <joint name="limby/0" type="hinge" class="normal_joint" range="-60 60" pos="-0.04 -0.04 0.0" axis="-0.5 0.5 0.7071"/>
        <geom name="limb/0" type="capsule" fromto="0.0 0.0 0.0 0.18 0.18 0.0" size="0.05" density="700"/>
        <site name="limb/mid/0" class="mirror_growth_site" pos="0.11 0.11 0.0"/>
        <site name="limb/btm/0" class="mirror_growth_site" pos="0.18 0.18 0.0"/>
        <site name="limb/btm_pos/0" class="btm_pos_site" pos="0.18 0.18 0.0"/>
        <site name="limb/touch/0" class="touch_site" size="0.060000000000000005" fromto="0.0 0.0 0.0 0.18 0.18 0.0" type="capsule"/>
        <body name="limb/10" pos="0.11 0.11 -0.05">
          <joint name="limby/10" type="hinge" class="normal_joint" range="0 90" pos="0.0 0.0 0.05" axis="0.0 1.0 0.0"/>
          <geom name="limb/10" type="capsule" fromto="0.0 0.0 0.0 0.0 0.0 -0.25" size="0.05" density="700"/>
          <site name="limb/mid/10" class="mirror_growth_site" pos="0.0 0.0 -0.15"/>
          <site name="limb/btm/10" class="mirror_growth_site" pos="0.0 0.0 -0.25"/>
          <site name="limb/btm_pos/10" class="btm_pos_site" pos="0.0 0.0 -0.25"/>
          <site name="limb/touch/10" class="touch_site" size="0.060000000000000005" fromto="0.0 0.0 0.0 0.0 0.0 -0.25" type="capsule"/>
          <body name="limb/14" pos="0.05 0.0 -0.15">
            <joint name="limbx/14" type="hinge" class="normal_joint" range="-45 0" pos="-0.05 0.0 0.0" axis="0.0 0.0 1.0"/>
            <geom name="limb/14" type="capsule" fromto="0.0 0.0 0.0 0.45 0.0 0.0" size="0.05" density="700"/>
            <site name="limb/mid/14" class="mirror_growth_site" pos="0.25 0.0 0.0"/>
            <site name="limb/btm/14" class="mirror_growth_site" pos="0.45 0.0 0.0"/>
            <site name="limb/btm_pos/14" class="btm_pos_site" pos="0.5 0.0 0.0"/>
            <site name="limb/touch/14" class="touch_site" size="0.060000000000000005" fromto="0.0 0.0 0.0 0.45 0.0 0.0" type="capsule"/>
          </body>
        </body>
      </body>
      <body name="limb/1" pos="0.07 -0.07 0.0">
        <joint name="limby/1" type="hinge" class="normal_joint" range="-60 60" pos="-0.04 0.04 0.0" axis="0.5 0.5 -0.7071"/>
        <geom name="limb/1" type="capsule" fromto="0.0 0.0 0.0 0.18 -0.18 0.0" size="0.05" density="700"/>
        <site name="limb/mid/1" class="mirror_growth_site" pos="0.11 -0.11 0.0"/>
        <site name="limb/btm/1" class="mirror_growth_site" pos="0.18 -0.18 0.0"/>
        <site name="limb/btm_pos/1" class="btm_pos_site" pos="0.18 -0.18 0.0"/>
        <site name="limb/touch/1" class="touch_site" size="0.060000000000000005" fromto="0.0 0.0 0.0 0.18 -0.18 0.0" type="capsule"/>
        <body name="limb/11" pos="0.11 -0.11 -0.05">
          <joint name="limby/11" type="hinge" class="normal_joint" range="0 90" pos="0.0 0.0 0.05" axis="0.0 1.0 0.0"/>
          <geom name="limb/11" type="capsule" fromto="0.0 0.0 0.0 0.0 0.0 -0.25" size="0.05" density="700"/>
          <site name="limb/mid/11" class="mirror_growth_site" pos="0.0 0.0 -0.15"/>
          <site name="limb/btm/11" class="mirror_growth_site" pos="0.0 0.0 -0.25"/>
          <site name="limb/btm_pos/11" class="btm_pos_site" pos="0.0 0.0 -0.25"/>
          <site name="limb/touch/11" class="touch_site" size="0.060000000000000005" fromto="0.0 0.0 0.0 0.0 0.0 -0.25" type="capsule"/>
          <body name="limb/15" pos="0.05 0.0 -0.15">
            <joint name="limbx/15" type="hinge" class="normal_joint" range="-45 0" pos="-0.05 0.0 0.0" axis="0.0 0.0 1.0"/>
            <geom name="limb/15" type="capsule" fromto="0.0 0.0 0.0 0.45 0.0 0.0" size="0.05" density="700"/>
            <site name="limb/mid/15" class="mirror_growth_site" pos="0.25 0.0 0.0"/>
            <site name="limb/btm/15" class="mirror_growth_site" pos="0.45 0.0 0.0"/>
            <site name="limb/btm_pos/15" class="btm_pos_site" pos="0.5 0.0 0.0"/>
            <site name="limb/touch/15" class="touch_site" size="0.060000000000000005" fromto="0.0 0.0 0.0 0.45 0.0 0.0" type="capsule"/>
          </body>
        </body>
      </body>
      <body name="limb/16" pos="-0.07 0.0 -0.07">
        <joint name="limbx/16" type="hinge" class="normal_joint" range="0 60" pos="0.04 0.0 0.04" axis="0.7071 0.0 -0.7071"/>
        <geom name="limb/16" type="capsule" fromto="0.0 0.0 0.0 -0.18 0.0 -0.18" size="0.05" density="700"/>
        <site name="limb/mid/16" class="growth_site" pos="-0.11 0.0 -0.11"/>
        <site name="limb/btm/16" class="growth_site" pos="-0.18 0.0 -0.18"/>
        <site name="limb/btm_pos/16" class="btm_pos_site" pos="-0.21 0.0 -0.21"/>
        <site name="limb/touch/16" class="touch_site" size="0.060000000000000005" fromto="0.0 0.0 0.0 -0.18 0.0 -0.18" type="capsule"/>
        <body name="limb/17" pos="-0.15 0.04 -0.11">
          <joint name="limbx/17" type="hinge" class="normal_joint" range="0 90" pos="0.04 -0.04 0.0" axis="0.5 0.5 -0.7071"/>
          <geom name="limb/17" type="capsule" fromto="0.0 0.0 0.0 -0.25 0.25 0.0" size="0.05" density="700"/>
          <site name="limb/mid/17" class="mirror_growth_site" pos="-0.14 0.14 0.0"/>
          <site name="limb/btm/17" class="mirror_growth_site" pos="-0.25 0.25 0.0"/>
          <site name="limb/btm_pos/17" class="btm_pos_site" pos="-0.28 0.28 0.0"/>
          <site name="limb/touch/17" class="touch_site" size="0.060000000000000005" fromto="0.0 0.0 0.0 -0.25 0.25 0.0" type="capsule"/>
        </body>
        <body name="limb/18" pos="-0.15 -0.04 -0.11">
          <joint name="limbx/18" type="hinge" class="normal_joint" range="0 90" pos="0.04 0.04 0.0" axis="0.5 -0.5 -0.7071"/>
          <geom name="limb/18" type="capsule" fromto="0.0 0.0 0.0 -0.25 -0.25 0.0" size="0.05" density="700"/>
          <site name="limb/mid/18" class="mirror_growth_site" pos="-0.14 -0.14 0.0"/>
          <site name="limb/btm/18" class="mirror_growth_site" pos="-0.25 -0.25 0.0"/>
          <site name="limb/btm_pos/18" class="btm_pos_site" pos="-0.28 -0.28 0.0"/>
          <site name="limb/touch/18" class="touch_site" size="0.060000000000000005" fromto="0.0 0.0 0.0 -0.25 -0.25 0.0" type="capsule"/>
        </body>
      </body>
    </body>
  </worldbody>
  <actuator>
    <motor joint="limby/0" gear="250" name="limby/0"/>
    <motor joint="limby/10" gear="200" name="limby/10"/>
    <motor joint="limbx/14" gear="250" name="limbx/14"/>
    <motor joint="limby/1" gear="250" name="limby/1"/>
    <motor joint="limby/11" gear="200" name="limby/11"/>
    <motor joint="limbx/15" gear="250" name="limbx/15"/>
    <motor joint="limbx/16" gear="200" name="limbx/16"/>
    <motor joint="limbx/17" gear="150" name="limbx/17"/>
    <motor joint="limbx/18" gear="150" name="limbx/18"/>
  </actuator>
  <sensor>
    <accelerometer name="torso_accel" site="root"/>
    <gyro name="torso_gyro" site="root"/>
    <velocimeter name="torso_vel" site="root"/>
    <subtreeangmom name="unimal_am" body="torso/0"/>
    <touch name="torso/0" site="torso/touch/0"/>
    <touch name="limb/0" site="limb/touch/0"/>
    <touch name="limb/10" site="limb/touch/10"/>
    <touch name="limb/14" site="limb/touch/14"/>
    <touch name="limb/1" site="limb/touch/1"/>
    <touch name="limb/11" site="limb/touch/11"/>
    <touch name="limb/15" site="limb/touch/15"/>
    <touch name="limb/16" site="limb/touch/16"/>
    <touch name="limb/17" site="limb/touch/17"/>
    <touch name="limb/18" site="limb/touch/18"/>
  </sensor>
  <!-- Add hfield assets -->
  <asset/>
  <!-- List of contacts to exclude -->
  <contact>
    <exclude name="limb/17:limb/18" body1="limb/17" body2="limb/18"/>
  </contact>
  <!-- Define material, texture etc -->
  <asset>
    <material name="grid" texture="grid" texrepeat="1 1" texuniform="true" reflectance="0.1"/>
    <material name="hfield" texture="hfield" texrepeat="1 1" texuniform="true" reflectance="0.1"/>
    <material name="wall" texture="wall" texrepeat="1 1" texuniform="true" reflectance=".5"/>
    <material name="platform" texture="platform" texrepeat="1 1" texuniform="true" reflectance=".5"/>
    <material name="boundary" texture="boundary" texrepeat="1 1" texuniform="true" reflectance=".5"/>
    <material name="jump" texture="jump" texrepeat="1 1" texuniform="true" reflectance=".5"/>
    <material name="goal" rgba="1 0 0 1"/>
    <material name="food" rgba="0 0 1 1" emission="1"/>
    <material name="init_position" rgba="0 1 0 0.7"/>
    <material name="self" rgba=".7 .5 .3 1"/>
    <material name="self_invisible" rgba=".7 .5 .3 0"/>
    <material name="self_default" rgba=".7 .5 .3 1"/>
    <material name="self_highlight" rgba="0 .5 .3 1"/>
    <material name="effector" rgba=".7 .4 .2 1"/>
    <material name="effector_default" rgba=".7 .4 .2 1"/>
    <material name="effector_highlight" rgba="0 .5 .3 1"/>
    <material name="decoration" rgba=".3 .5 .7 1"/>
    <material name="eye" rgba="0 .2 1 1"/>
    <material name="target" rgba=".6 .3 .3 1"/>
    <material name="target_default" rgba=".6 .3 .3 1"/>
    <material name="target_highlight" rgba=".6 .3 .3 .4"/>
    <material name="site" rgba=".5 .5 .5 .3"/>
    <material name="ball" texture="ball"/>
  </asset>
  <asset>
    <texture name="grid" type="2d" builtin="checker" rgb1="0.4 0.4 0.4" rgb2="0.4 0.4 0.4" width="300" height="300" mark="edge" markrgb="0.2 0.2 0.2"/>
    <texture name="hfield" type="2d" builtin="checker" rgb1="0.4 0.4 0.4" rgb2="0.4 0.4 0.4" width="300" height="300" mark="edge" markrgb="0.2 0.2 0.2"/>
    <texture name="wall" type="2d" builtin="flat" rgb1="0.9 0.7 0" rgb2="0.9 0.7 0" width="300" height="300"/>
    <texture name="platform" type="2d" builtin="flat" rgb1="0.3 0 0.8" rgb2="0.3 0 0.8" width="300" height="300"/>
    <texture name="boundary" type="2d" builtin="flat" rgb1="0.3 0.3 0.3" rgb2="0.3 0.3 0.3" width="300" height="300"/>
    <texture name="jump" type="2d" builtin="flat" rgb1="0.3 0.3 0.3" rgb2="0.3 0.3 0.3" width="300" height="300"/>
    <texture name="skybox" type="skybox" builtin="gradient" rgb1="1 1 1" rgb2="0.6 0.6 0.6" width="800" height="800"/>
    <texture name="ball" builtin="checker" mark="cross" width="151" height="151" rgb1="0.1 0.1 0.1" rgb2="0.9 0.9 0.9" markrgb="1 1 1"/>
  </asset>
  <visual>
    <headlight ambient="0.6 0.6 0.6" diffuse="0.3 0.3 0.3" specular="0 0 0"/>
    <map znear=".01" shadowclip="0.5"/>
    <quality shadowsize="16384"/>
  </visual>
</mujoco>
