<?xml version='1.0' encoding='UTF-8'?>
<!-- Universal Animal Template: unimal -->
<mujoco model="unimal">
  <compiler angle="degree"/>
  <size njmax="2000" nconmax="500"/>
  <option timestep=".005">
    <flag filterparent="disable"/>
  </option>
  <!-- Common defaults to make search space tractable -->
  <default>
    <!-- Define motor defaults -->
    <motor ctrlrange="-1 1" ctrllimited="true"/>
    <!-- Define joint defaults -->
    <default class="normal_joint">
      <joint type="hinge" damping="1" stiffness="1" armature="1" limited="true" range="-120 120" solimplimit="0 0.99 0.01"/>
    </default>
    <default class="walker_joint">
      <joint type="hinge" damping="0.2" stiffness="1" armature=".01" limited="true" range="-120 120" solimplimit="0 0.99 0.01"/>
    </default>
    <default class="stiff_joint">
      <joint type="hinge" damping="5" stiffness="10" armature=".01" limited="true" solimplimit="0 0.99 0.01"/>
    </default>
    <default class="free">
      <joint limited="false" damping="0" armature="0" stiffness="0"/>
    </default>
    <default class="growth_site">
      <site size="1e-6 1e-6 1e-6"/>
    </default>
    <default class="torso_growth_site">
      <site size="1e-6 1e-6 1e-6"/>
    </default>
    <default class="mirror_growth_site">
      <site size="1e-6 1e-6 1e-6"/>
    </default>
    <default class="btm_pos_site">
      <site size="1e-6 1e-6 1e-6"/>
    </default>
    <default class="box_face_site">
      <site size="1e-6 1e-6 1e-6"/>
    </default>
    <default class="imu_vel">
      <site type="box" size="0.05" rgba="1 0 0 0"/>
    </default>
    <default class="touch_site">
      <site group="3" rgba="0 0 1 .3"/>
    </default>
    <default class="food_site">
      <site material="food" size="0.15"/>
    </default>
    <!-- Define geom defaults -->
    <geom type="capsule" condim="3" friction="0.7 0.1 0.1" material="self"/>
  </default>
  <worldbody>
    <light diffuse="1 1 1" directional="true" exponent="1" pos="0 0 8" specular="0.1 0.1 0.1" dir="0 0 -1"/>
    <!-- <geom name="floor" type="plane" pos="0 0 0" size="50 50 1" material="grid"/> -->
    <!-- Programatically generated xml goes here -->
    <body name="torso/0" pos="0 0 1.5">
      <joint name="root" type="free" class="free"/>
      <site name="root" class="imu_vel"/>
      <geom name="torso/0" type="sphere" size="0.1" condim="3" density="800"/>
      <camera name="side" pos="0 -7 2" xyaxes="1 0 0 0 1 2" mode="trackcom"/>
      <site name="torso/0" class="growth_site" pos="0 0 0"/>
      <site name="torso/btm_pos/0" class="btm_pos_site" pos="0 0 -0.1"/>
      <site name="torso/touch/0" class="touch_site" size="0.11"/>
      <site name="torso/horizontal_y/0" class="torso_growth_site" pos="-0.1 0 0"/>
      <body name="limb/0" pos="-0.07 0.0 -0.07">
        <joint name="limbx/0" type="hinge" class="normal_joint" range="-45 45" pos="0.04 0.0 0.04" axis="0.7071 0.0 -0.7071"/>
        <joint name="limby/0" type="hinge" class="normal_joint" range="-30 30" pos="0.04 0.0 0.04" axis="0.0 1.0 0.0"/>
        <geom name="limb/0" type="capsule" fromto="0.0 0.0 0.0 -0.18 0.0 -0.18" size="0.05" density="500"/>
        <site name="limb/mid/0" class="growth_site" pos="-0.11 0.0 -0.11"/>
        <site name="limb/btm/0" class="growth_site" pos="-0.18 0.0 -0.18"/>
        <site name="limb/btm_pos/0" class="btm_pos_site" pos="-0.18 0.0 -0.18"/>
        <site name="limb/touch/0" class="touch_site" size="0.060000000000000005" fromto="0.0 0.0 0.0 -0.18 0.0 -0.18" type="capsule"/>
        <body name="limb/14" pos="-0.22 0.0 -0.22">
          <joint name="limbx/14" type="hinge" class="normal_joint" range="0 90" pos="0.04 0.0 0.04" axis="0.7071 0.0 -0.7071"/>
          <geom name="limb/14" type="capsule" fromto="0.0 0.0 0.0 -0.18 0.0 -0.18" size="0.05" density="500"/>
          <site name="limb/mid/14" class="growth_site" pos="-0.11 0.0 -0.11"/>
          <site name="limb/btm/14" class="growth_site" pos="-0.18 0.0 -0.18"/>
          <site name="limb/btm_pos/14" class="btm_pos_site" pos="-0.18 0.0 -0.18"/>
          <site name="limb/touch/14" class="touch_site" size="0.060000000000000005" fromto="0.0 0.0 0.0 -0.18 0.0 -0.18" type="capsule"/>
          <body name="limb/25" pos="-0.11 0.0 -0.16">
            <joint name="limby/25" type="hinge" class="normal_joint" range="-60 60" pos="0.0 0.0 0.05" axis="0.0 1.0 0.0"/>
            <geom name="limb/25" type="capsule" fromto="0.0 0.0 0.0 0.0 0.0 -0.35" size="0.05" density="500"/>
            <site name="limb/mid/25" class="growth_site" pos="0.0 0.0 -0.2"/>
            <site name="limb/btm/25" class="growth_site" pos="0.0 0.0 -0.35"/>
            <site name="limb/btm_pos/25" class="btm_pos_site" pos="0.0 0.0 -0.4"/>
            <site name="limb/touch/25" class="touch_site" size="0.060000000000000005" fromto="0.0 0.0 0.0 0.0 0.0 -0.35" type="capsule"/>
            <body name="limb/28" pos="0.0 0.0 -0.39999999999999997">
              <joint name="limby/28" type="hinge" class="normal_joint" range="-45 0" pos="0.0 0.0 0.05" axis="0.0 1.0 0.0"/>
              <geom name="limb/28" type="capsule" fromto="0.0 0.0 0.0 0.0 0.0 -0.35" size="0.05" density="500"/>
              <site name="limb/mid/28" class="growth_site" pos="0.0 0.0 -0.2"/>
              <site name="limb/btm/28" class="growth_site" pos="0.0 0.0 -0.35"/>
              <site name="limb/btm_pos/28" class="btm_pos_site" pos="0.0 0.0 -0.4"/>
              <site name="limb/touch/28" class="touch_site" size="0.060000000000000005" fromto="0.0 0.0 0.0 0.0 0.0 -0.35" type="capsule"/>
              <body name="limb/30" pos="0.0 0.04 -0.24000000000000002">
                <joint name="limby/30" type="hinge" class="normal_joint" range="-30 0" pos="0.0 -0.04 0.04" axis="0.0 0.7071 0.7071"/>
                <geom name="limb/30" type="capsule" fromto="0.0 0.0 0.0 0.0 0.18 -0.18" size="0.05" density="500"/>
                <site name="limb/mid/30" class="mirror_growth_site" pos="0.0 0.11 -0.11"/>
                <site name="limb/btm/30" class="mirror_growth_site" pos="0.0 0.18 -0.18"/>
                <site name="limb/btm_pos/30" class="btm_pos_site" pos="0.0 0.21 -0.21"/>
                <site name="limb/touch/30" class="touch_site" size="0.060000000000000005" fromto="0.0 0.0 0.0 0.0 0.18 -0.18" type="capsule"/>
              </body>
              <body name="limb/31" pos="0.0 -0.04 -0.24000000000000002">
                <joint name="limby/31" type="hinge" class="normal_joint" range="-30 0" pos="0.0 0.04 0.04" axis="-0.0 0.7071 -0.7071"/>
                <geom name="limb/31" type="capsule" fromto="0.0 0.0 0.0 0.0 -0.18 -0.18" size="0.05" density="500"/>
                <site name="limb/mid/31" class="mirror_growth_site" pos="0.0 -0.11 -0.11"/>
                <site name="limb/btm/31" class="mirror_growth_site" pos="0.0 -0.18 -0.18"/>
                <site name="limb/btm_pos/31" class="btm_pos_site" pos="0.0 -0.21 -0.21"/>
                <site name="limb/touch/31" class="touch_site" size="0.060000000000000005" fromto="0.0 0.0 0.0 0.0 -0.18 -0.18" type="capsule"/>
              </body>
            </body>
          </body>
        </body>
        <body name="limb/23" pos="-0.06 0.0 -0.11">
          <joint name="limbx/23" type="hinge" class="normal_joint" range="-60 60" pos="-0.05 0.0 0.0" axis="0.0 0.0 1.0"/>
          <joint name="limby/23" type="hinge" class="normal_joint" range="-60 30" pos="-0.05 0.0 0.0" axis="-0.0 1.0 0.0"/>
          <geom name="limb/23" type="capsule" fromto="0.0 0.0 0.0 0.45 0.0 0.0" size="0.05" density="500"/>
          <site name="limb/mid/23" class="growth_site" pos="0.25 0.0 0.0"/>
          <site name="limb/btm/23" class="growth_site" pos="0.45 0.0 0.0"/>
          <site name="limb/btm_pos/23" class="btm_pos_site" pos="0.45 0.0 0.0"/>
          <site name="limb/touch/23" class="touch_site" size="0.060000000000000005" fromto="0.0 0.0 0.0 0.45 0.0 0.0" type="capsule"/>
          <body name="limb/29" pos="0.25 0.0 -0.05">
            <joint name="limby/29" type="hinge" class="normal_joint" range="-30 30" pos="0.0 0.0 0.05" axis="0.0 1.0 0.0"/>
            <geom name="limb/29" type="capsule" fromto="0.0 0.0 0.0 0.0 0.0 -0.45" size="0.05" density="500"/>
            <site name="limb/mid/29" class="growth_site" pos="0.0 0.0 -0.25"/>
            <site name="limb/btm/29" class="growth_site" pos="0.0 0.0 -0.45"/>
            <site name="limb/btm_pos/29" class="btm_pos_site" pos="0.0 0.0 -0.5"/>
            <site name="limb/touch/29" class="touch_site" size="0.060000000000000005" fromto="0.0 0.0 0.0 0.0 0.0 -0.45" type="capsule"/>
          </body>
        </body>
      </body>
    </body>
  </worldbody>
  <actuator>
    <motor joint="limbx/0" gear="150" name="limbx/0"/>
    <motor joint="limby/0" gear="250" name="limby/0"/>
    <motor joint="limbx/14" gear="150" name="limbx/14"/>
    <motor joint="limby/25" gear="300" name="limby/25"/>
    <motor joint="limby/28" gear="300" name="limby/28"/>
    <motor joint="limby/30" gear="300" name="limby/30"/>
    <motor joint="limby/31" gear="300" name="limby/31"/>
    <motor joint="limbx/23" gear="300" name="limbx/23"/>
    <motor joint="limby/23" gear="150" name="limby/23"/>
    <motor joint="limby/29" gear="150" name="limby/29"/>
  </actuator>
  <sensor>
    <accelerometer name="torso_accel" site="root"/>
    <gyro name="torso_gyro" site="root"/>
    <velocimeter name="torso_vel" site="root"/>
    <subtreeangmom name="unimal_am" body="torso/0"/>
    <touch name="torso/0" site="torso/touch/0"/>
    <touch name="limb/0" site="limb/touch/0"/>
    <touch name="limb/14" site="limb/touch/14"/>
    <touch name="limb/25" site="limb/touch/25"/>
    <touch name="limb/28" site="limb/touch/28"/>
    <touch name="limb/30" site="limb/touch/30"/>
    <touch name="limb/31" site="limb/touch/31"/>
    <touch name="limb/23" site="limb/touch/23"/>
    <touch name="limb/29" site="limb/touch/29"/>
  </sensor>
  <!-- Add hfield assets -->
  <asset/>
  <!-- List of contacts to exclude -->
  <contact>
    <exclude name="limb/30:limb/31" body1="limb/30" body2="limb/31"/>
  </contact>
  <!-- Define material, texture etc -->
  <asset>
    <material name="grid" texture="grid" texrepeat="1 1" texuniform="true" reflectance="0.1"/>
    <material name="hfield" texture="hfield" texrepeat="1 1" texuniform="true" reflectance="0.1"/>
    <material name="wall" texture="wall" texrepeat="1 1" texuniform="true" reflectance=".5"/>
    <material name="platform" texture="platform" texrepeat="1 1" texuniform="true" reflectance=".5"/>
    <material name="boundary" texture="boundary" texrepeat="1 1" texuniform="true" reflectance=".5"/>
    <material name="jump" texture="jump" texrepeat="1 1" texuniform="true" reflectance=".5"/>
    <material name="goal" rgba="1 0 0 1"/>
    <material name="food" rgba="0 0 1 1" emission="1"/>
    <material name="init_position" rgba="0 1 0 0.7"/>
    <material name="self" rgba=".7 .5 .3 1"/>
    <material name="self_invisible" rgba=".7 .5 .3 0"/>
    <material name="self_default" rgba=".7 .5 .3 1"/>
    <material name="self_highlight" rgba="0 .5 .3 1"/>
    <material name="effector" rgba=".7 .4 .2 1"/>
    <material name="effector_default" rgba=".7 .4 .2 1"/>
    <material name="effector_highlight" rgba="0 .5 .3 1"/>
    <material name="decoration" rgba=".3 .5 .7 1"/>
    <material name="eye" rgba="0 .2 1 1"/>
    <material name="target" rgba=".6 .3 .3 1"/>
    <material name="target_default" rgba=".6 .3 .3 1"/>
    <material name="target_highlight" rgba=".6 .3 .3 .4"/>
    <material name="site" rgba=".5 .5 .5 .3"/>
    <material name="ball" texture="ball"/>
  </asset>
  <asset>
    <texture name="grid" type="2d" builtin="checker" rgb1="0.4 0.4 0.4" rgb2="0.4 0.4 0.4" width="300" height="300" mark="edge" markrgb="0.2 0.2 0.2"/>
    <texture name="hfield" type="2d" builtin="checker" rgb1="0.4 0.4 0.4" rgb2="0.4 0.4 0.4" width="300" height="300" mark="edge" markrgb="0.2 0.2 0.2"/>
    <texture name="wall" type="2d" builtin="flat" rgb1="0.9 0.7 0" rgb2="0.9 0.7 0" width="300" height="300"/>
    <texture name="platform" type="2d" builtin="flat" rgb1="0.3 0 0.8" rgb2="0.3 0 0.8" width="300" height="300"/>
    <texture name="boundary" type="2d" builtin="flat" rgb1="0.3 0.3 0.3" rgb2="0.3 0.3 0.3" width="300" height="300"/>
    <texture name="jump" type="2d" builtin="flat" rgb1="0.3 0.3 0.3" rgb2="0.3 0.3 0.3" width="300" height="300"/>
    <texture name="skybox" type="skybox" builtin="gradient" rgb1="1 1 1" rgb2="0.6 0.6 0.6" width="800" height="800"/>
    <texture name="ball" builtin="checker" mark="cross" width="151" height="151" rgb1="0.1 0.1 0.1" rgb2="0.9 0.9 0.9" markrgb="1 1 1"/>
  </asset>
  <visual>
    <headlight ambient="0.6 0.6 0.6" diffuse="0.3 0.3 0.3" specular="0 0 0"/>
    <map znear=".01" shadowclip="0.5"/>
    <quality shadowsize="16384"/>
  </visual>
</mujoco>
